프라미스가 거부되면 제어 흐름이 제일 가까운 rejection 핸들러로 넘어가서 체인을 사용하면 에러를 쉽게 처리할 수 있다

사이트 주소가 잘못된 경우
```js
fetch('https://no-such-server.blabla') // 거부
  .then(response => response.json())
  .catch(err => alert(err)) // TypeError: failed to fetch (출력되는 내용은 다를 수 있음)
```

응답으로 받은 JSON의 형식이 잘못된 경우 가장 쉬운 에러 처리 방법은 체인 끝에 .catch를 붙이는 것
```js
fetch('/article/promise-chaining/user.json')
  .then(response => response.json())
  .then(user => fetch(`https://api.github.com/users/${user.name}`))
  .then(response => response.json())
  .then(githubUser => new Promise((resolve, reject) => {
    let img = document.createElement('img');
    img.src = githubUser.avatar_url;
    img.className = "promise-avatar-example";
    document.body.append(img);

    setTimeout(() => {
      img.remove();
      resolve(githubUser);
    }, 3000);
  }))
  .catch(error => alert(error.message));
```

### 암시적 try...catch
프라미스 executor와 프라미스 핸들러 코드 주위엔 보이지 않는 try...catch가 있다
예외가 발생하면 암시적 try...catch에서 예외를 잡고 이를 reject 처럼 다룸

```js
new Promise((resolve, reject) => {
  throw new Error("에러 발생!");
}).catch(alert); // Error: 에러 발생!
```
위 예시는 아래 예시와 똑같이 동작
```js
new Promise((resolve, reject) => {
  reject(new Error("에러 발생!"));
}).catch(alert); // Error: 에러 발생!
```
executor 주위의 암시적 try...catch는 스스로 에러를 잡고, 에러를 거부상태의 프라미스로 변경 시킨다. `.then` 핸들러 안에서 `throw`를 사용해 에러를 던지면, 이 자체가 거부된 프라미스를 의미하게 됩니다. 따라서 제어 흐름이 가장 가까운 에러 핸들러로 넘어갑니다.

이런일은 핸들러에서도 발생
```js
new Promise((resolve, reject) => {
  resolve("OK");
}).then((result) => {
  throw new Error("에러 발생!"); // 프라미스가 거부됨
}).catch(alert); // Error: 에러 발생!
```

```js
new Promise((resolve, reject) => {
  resolve("OK");
}).then((result) => {
  blabla(); // 존재하지 않는 함수
}).catch(alert); // ReferenceError: blabla is not defined
```
### 다시 던지기
마지막 catch은 try...catch와 유사한 역할을 한다
```js
// 실행 순서: catch -> then
new Promise((resolve, reject) => {

  throw new Error("에러 발생!");

}).catch(function(error) {

  alert("에러가 잘 처리되었습니다. 정상적으로 실행이 이어집니다.");

}).then(() => alert("다음 핸들러가 실행됩니다."));
```

```js
// 실행 순서: catch -> catch
new Promise((resolve, reject) => {

  throw new Error("에러 발생!");

}).catch(function(error) { // (*)

  if (error instanceof URIError) {
    // 에러 처리
  } else {
    alert("처리할 수 없는 에러");

    throw error; // 에러 다시 던지기
  }

}).then(function() {
  /* 여기는 실행되지 않습니다. */
}).catch(error => { // (**)

  alert(`알 수 없는 에러가 발생함: ${error}`);
  // 반환값이 없음 => 실행이 계속됨

});
```


### 처리되지 못한 거부
```js
new Promise(function() {
  noSuchFunction(); // 존재하지 않는 함수를 호출하기 때문에 에러가 발생함
})
  .then(() => {
    // 성공상태의 프라미스를 처리하는 핸들러. 한 개 혹은 여러 개가 있을 수 있음
  }); // 끝에 .catch가 없음!
```
예외를 처리해 줄 핸들러가 없어서 에러가 ‘갇혀버립니다’. 에러를 처리할 코드가 없기 때문

브라우저에서는 unhandledrejection 이벤트로 처리할 수 있습니다.
```js
window.addEventListener('unhandledrejection', function(event) {
  // unhandledrejection 이벤트엔 두 개의 특수 프로퍼티가 있습니다.
  alert(event.promise); // [object Promise] - 에러를 생성하는 프라미스
  alert(event.reason); // Error: 에러 발생! - 처리하지 못한 에러 객체
});

new Promise(function() {
  throw new Error("에러 발생!");
}); // 에러를 처리할 수 있는 .catch 핸들러가 없음
```

### 요약
- `.catch` 는 프라미스에서 발생한 모든 에러를 다룹니다. `reject()`가 호출되거나 에러가 던져지면 `.catch`에서 이를 처리합니다.
- `.catch`는 에러를 처리하고 싶은 지점에 정확히 위치시켜야 합니다. 물론 어떻게 에러를 처리할지 알고 있어야 하죠. 핸들러에선 에러를 분석하고(커스텀 에러 클래스가 이때 도움이 됩니다) 알 수 없는 에러(프로그래밍 실수로 발생한 에러일 확률이 높습니다)는 다시 던질 수 있습니다.
- 에러 발생 시, 회복할 방법이 없다면 `.catch`를 사용하지 않아도 괜찮습니다.
- `unhandledrejection` 이벤트 핸들러를 사용해 처리되지 않은 에러를 추적하고, 이를 사용자(혹은 서버에)에게 알려서 애플리케이션이 아무런 설명도 없이 ‘그냥 죽는걸’ 방지합시다. 브라우저 환경에선 예방에 `unhandledrejection`을, 다른 환경에선 유사한 핸들러를 사용할 수 있습니다.

### 과제
#### setTimeout에서의 에러
아래 예시에서 .catch가 트리거 될까요? 이유와 함께 .catch가 트리거 될지 안 될지를 맞춰보세요.

```js
new Promise(function(resolve, reject) {
  setTimeout(() => {
    throw new Error("에러 발생!");
  }, 1000);
}).catch(alert);
```

나의 답: 트리거 되지 않는다 에러가 나중에 발생하므로

해답: 
.catch는 트리거 되지 않습니다.

```js
new Promise(function(resolve, reject) {
  setTimeout(() => {
    throw new Error("에러 발생!");
  }, 1000);
}).catch(alert);
```

이 챕터에서 언급했듯이, '암시적 try..catch'가 함수 코드를 감싸고 있으므로 모든 동기적 에러는 '암시적 try..catch'에서 처리됩니다.

하지만 여기에서 에러는 executor(실행자, 실행 함수)가 실행되는 동안이 아니라 나중에 발생합니다. 따라서 프라미스는 에러를 처리할 수 없습니다.